
  You can now view your Streamlit app in your browser.

  URL: http://0.0.0.0:8501


  You can now view your Streamlit app in your browser.

  URL: http://0.0.0.0:8501

2024-12-30 12:54:54.454 Uncaught app exception
Traceback (most recent call last):
  File "/Users/undo/anaconda3/lib/python3.10/site-packages/streamlit/runtime/scriptrunner/exec_code.py", line 88, in exec_func_with_error_handling
    result = func()
  File "/Users/undo/anaconda3/lib/python3.10/site-packages/streamlit/runtime/scriptrunner/script_runner.py", line 579, in code_to_exec
    exec(code, module.__dict__)
  File "/Users/undo/Desktop/love-storage/workspace/main.py", line 22, in <module>
    exec(code)
  File "<string>", line 128, in <module>
  File "<string>", line 38, in insert_entry
psycopg2.errors.StringDataRightTruncation: value too long for type character varying(255)

2024-12-30 20:05:28.055 Uncaught app exception
Traceback (most recent call last):
  File "/Users/undo/anaconda3/lib/python3.10/site-packages/streamlit/elements/image.py", line 385, in image_to_url
    with open(image, "rb") as f:
FileNotFoundError: [Errno 2] No such file or directory: '/Users/undo/Desktop/love-storage/workspace/images/photos/2024/11/23/IMG_8909.jpeg'

During handling of the above exception, another exception occurred:

Traceback (most recent call last):
  File "/Users/undo/anaconda3/lib/python3.10/site-packages/streamlit/runtime/memory_media_file_storage.py", line 164, in _read_file
    with open(filename, "rb") as f:
FileNotFoundError: [Errno 2] No such file or directory: '/Users/undo/Desktop/love-storage/workspace/images/photos/2024/11/23/IMG_8909.jpeg'

The above exception was the direct cause of the following exception:

Traceback (most recent call last):
  File "/Users/undo/anaconda3/lib/python3.10/site-packages/streamlit/runtime/scriptrunner/exec_code.py", line 88, in exec_func_with_error_handling
    result = func()
  File "/Users/undo/anaconda3/lib/python3.10/site-packages/streamlit/runtime/scriptrunner/script_runner.py", line 579, in code_to_exec
    exec(code, module.__dict__)
  File "/Users/undo/Desktop/love-storage/workspace/main.py", line 22, in <module>
    exec(code)
  File "<string>", line 157, in <module>
  File "/Users/undo/anaconda3/lib/python3.10/site-packages/streamlit/runtime/metrics_util.py", line 410, in wrapped_func
    result = non_optional_func(*args, **kwargs)
  File "/Users/undo/anaconda3/lib/python3.10/site-packages/streamlit/elements/image.py", line 162, in image
    marshall_images(
  File "/Users/undo/anaconda3/lib/python3.10/site-packages/streamlit/elements/image.py", line 546, in marshall_images
    proto_img.url = image_to_url(
  File "/Users/undo/anaconda3/lib/python3.10/site-packages/streamlit/elements/image.py", line 397, in image_to_url
    url = runtime.get_instance().media_file_mgr.add(image, mimetype, image_id)
  File "/Users/undo/anaconda3/lib/python3.10/site-packages/streamlit/runtime/media_file_manager.py", line 226, in add
    file_id = self._storage.load_and_get_id(
  File "/Users/undo/anaconda3/lib/python3.10/site-packages/streamlit/runtime/memory_media_file_storage.py", line 115, in load_and_get_id
    file_data = self._read_file(path_or_data)
  File "/Users/undo/anaconda3/lib/python3.10/site-packages/streamlit/runtime/memory_media_file_storage.py", line 167, in _read_file
    raise MediaFileStorageError(f"Error opening '{filename}'") from ex
streamlit.runtime.media_file_storage.MediaFileStorageError: Error opening '/Users/undo/Desktop/love-storage/workspace/images/photos/2024/11/23/IMG_8909.jpeg'
2024-12-30 20:05:34.334 Uncaught app exception
Traceback (most recent call last):
  File "/Users/undo/anaconda3/lib/python3.10/site-packages/streamlit/elements/image.py", line 385, in image_to_url
    with open(image, "rb") as f:
FileNotFoundError: [Errno 2] No such file or directory: '/Users/undo/Desktop/love-storage/workspace/images/photos/2024/11/23/IMG_8909.jpeg'

During handling of the above exception, another exception occurred:

Traceback (most recent call last):
  File "/Users/undo/anaconda3/lib/python3.10/site-packages/streamlit/runtime/memory_media_file_storage.py", line 164, in _read_file
    with open(filename, "rb") as f:
FileNotFoundError: [Errno 2] No such file or directory: '/Users/undo/Desktop/love-storage/workspace/images/photos/2024/11/23/IMG_8909.jpeg'

The above exception was the direct cause of the following exception:

Traceback (most recent call last):
  File "/Users/undo/anaconda3/lib/python3.10/site-packages/streamlit/runtime/scriptrunner/exec_code.py", line 88, in exec_func_with_error_handling
    result = func()
  File "/Users/undo/anaconda3/lib/python3.10/site-packages/streamlit/runtime/scriptrunner/script_runner.py", line 579, in code_to_exec
    exec(code, module.__dict__)
  File "/Users/undo/Desktop/love-storage/workspace/main.py", line 22, in <module>
    exec(code)
  File "<string>", line 157, in <module>
  File "/Users/undo/anaconda3/lib/python3.10/site-packages/streamlit/runtime/metrics_util.py", line 410, in wrapped_func
    result = non_optional_func(*args, **kwargs)
  File "/Users/undo/anaconda3/lib/python3.10/site-packages/streamlit/elements/image.py", line 162, in image
    marshall_images(
  File "/Users/undo/anaconda3/lib/python3.10/site-packages/streamlit/elements/image.py", line 546, in marshall_images
    proto_img.url = image_to_url(
  File "/Users/undo/anaconda3/lib/python3.10/site-packages/streamlit/elements/image.py", line 397, in image_to_url
    url = runtime.get_instance().media_file_mgr.add(image, mimetype, image_id)
  File "/Users/undo/anaconda3/lib/python3.10/site-packages/streamlit/runtime/media_file_manager.py", line 226, in add
    file_id = self._storage.load_and_get_id(
  File "/Users/undo/anaconda3/lib/python3.10/site-packages/streamlit/runtime/memory_media_file_storage.py", line 115, in load_and_get_id
    file_data = self._read_file(path_or_data)
  File "/Users/undo/anaconda3/lib/python3.10/site-packages/streamlit/runtime/memory_media_file_storage.py", line 167, in _read_file
    raise MediaFileStorageError(f"Error opening '{filename}'") from ex
streamlit.runtime.media_file_storage.MediaFileStorageError: Error opening '/Users/undo/Desktop/love-storage/workspace/images/photos/2024/11/23/IMG_8909.jpeg'
